<?xml version="1.0" ?>
<!-- =================================================================================== -->
<!-- |    This document was autogenerated by xacro from /root/ibrido_ws/src/iit-kyon-ros-pkg/kyon_urdf/urdf/kyon.urdf.xacro | -->
<!-- |    EDITING THIS FILE BY HAND IS NOT RECOMMENDED                                 | -->
<!-- =================================================================================== -->
<robot name="kyon">
  <!-- scaling factor for available peack torque link side, from 0 to 1 -->
  <material name="black">
    <color rgba="0.4 0.4 0.4 1"/>
  </material>
  <material name="dark_grey">
    <color rgba="0.1 0.1 0.1 1"/>
  </material>
  <!-- Compound properties (i.e. based on the props parsed from the yaml) -->
  <!-- Compound properties (i.e. based on the props parsed from the yaml) -->
  <link name="base_link"/>
  <joint name="base_joint" type="fixed">
    <parent link="base_link"/>
    <child link="pelvis"/>
    <origin rpy="0 0 0" xyz="0 0 0"/>
  </joint>
  <link name="pelvis">
    <inertial>
      <origin xyz="0.0 0.0 0.0"/>
      <mass value="14"/>
      <inertia ixx="0.28291666666666665" ixy="0.0" ixz="0.0" iyy="0.7933333333333334" iyz="0.0" izz="0.9829166666666667"/>
    </inertial>
    <visual>
      <origin rpy="0.0 0.0 0.0" xyz="0.0 0 0.0"/>
      <geometry>
        <box size="0.8 0.45 0.2"/>
        <!--mesh filename="package://kyon_urdf/meshes/mesh_pelvis.stl" scale="0.001 0.001 0.001"/-->
      </geometry>
    </visual>
    <collision>
      <origin rpy="0.0 0.0 0.0" xyz="0.0 0 0.0"/>
      <geometry>
        <box size="0.8 0.45 0.2"/>
        <!--mesh filename="package://kyon_urdf/meshes/mesh_pelvis.stl" scale="0.001 0.001 0.001"/-->
      </geometry>
    </collision>
  </link>
  <!-- /macro legs -->
  <!-- links -->
  <link name="hip_roll_motor_1">
    <inertial>
      <origin xyz="0.0 0.0 0.0"/>
      <mass value="1.8"/>
      <inertia ixx="0.001893666666666667" ixy="0.0" ixz="0.0" iyy="0.001893666666666667" iyz="0.0" izz="0.002254000000000001"/>
    </inertial>
    <visual>
      <origin rpy="0.0 0.0 0.0" xyz="0.0 0.0 0.0"/>
      <geometry>
        <cylinder length="0.1" radius="0.07"/>
      </geometry>
      <material name="dark_grey"/>
    </visual>
    <collision>
      <origin rpy="0.0 0.0 0.0" xyz="0.0 0.0 0.0"/>
      <geometry>
        <cylinder length="0.1" radius="0.07"/>
      </geometry>
    </collision>
  </link>
  <link name="hip_pitch_motor_1">
    <inertial>
      <origin xyz="0.0 0.0 0.0"/>
      <mass value="1.8"/>
      <inertia ixx="0.001893666666666667" ixy="0.0" ixz="0.0" iyy="0.001893666666666667" iyz="0.0" izz="0.002254000000000001"/>
    </inertial>
    <visual>
      <origin rpy="0.0 0.0 0.0" xyz="0.0 0.0 0.0"/>
      <geometry>
        <cylinder length="0.1" radius="0.07"/>
      </geometry>
      <material name="dark_grey"/>
    </visual>
    <collision>
      <origin rpy="0.0 0.0 0.0" xyz="0.0 0.0 0.0"/>
      <geometry>
        <cylinder length="0.1" radius="0.07"/>
      </geometry>
    </collision>
  </link>
  <link name="knee_pitch_motor_1">
    <inertial>
      <origin xyz="0.0 0.0 0.0"/>
      <mass value="1.8"/>
      <inertia ixx="0.001893666666666667" ixy="0.0" ixz="0.0" iyy="0.001893666666666667" iyz="0.0" izz="0.002254000000000001"/>
    </inertial>
    <visual>
      <origin rpy="0.0 0.0 0.0" xyz="0.0 0.0 0.0"/>
      <geometry>
        <cylinder length="0.1" radius="0.07"/>
      </geometry>
      <material name="dark_grey"/>
    </visual>
    <collision>
      <origin rpy="0.0 0.0 0.0" xyz="0.0 0.0 0.0"/>
      <geometry>
        <cylinder length="0.1" radius="0.07"/>
      </geometry>
    </collision>
  </link>
  <link name="upper_leg_1">
    <inertial>
      <origin xyz="0.175 0.0 0.0"/>
      <mass value="2.0"/>
      <inertia ixx="0.003333333333333334" ixy="0.0" ixz="0.0" iyy="0.02208333333333333" iyz="0.0" izz="0.02208333333333333"/>
    </inertial>
    <origin rpy="0.0 0.0 0.0" xyz="0.0 0.0 0.0"/>
    <visual>
      <origin rpy="0.0 0.0 0.0" xyz="0.175 0.0 0.0"/>
      <geometry>
        <box size="0.35 0.1 0.1"/>
      </geometry>
      <material name="dark_grey"/>
    </visual>
    <collision>
      <origin rpy="0.0 0.0 0.0" xyz="0.175 0.0 0.0"/>
      <geometry>
        <box size="0.35 0.1 0.1"/>
      </geometry>
    </collision>
  </link>
  <link name="lower_leg_1">
    <inertial>
      <origin xyz="0.15 0.0 0.0"/>
      <mass value="1.0"/>
      <inertia ixx="0.00041666666666666675" ixy="0.0" ixz="0.0" iyy="0.007708333333333333" iyz="0.0" izz="0.007708333333333333"/>
    </inertial>
    <visual>
      <origin rpy="0.0 0.0 0.0" xyz="0.15 0.0 0.0"/>
      <geometry>
        <box size="0.3 0.05 0.05"/>
      </geometry>
      <material name="dark_grey"/>
    </visual>
    <collision>
      <origin rpy="0.0 0.0 0.0" xyz="0.15 0.0 0.0"/>
      <geometry>
        <box size="0.3 0.05 0.05"/>
      </geometry>
    </collision>
  </link>
  <link name="ball_1">
    <inertial>
      <origin xyz="0.0 0.0 0.0"/>
      <mass value="0.1"/>
      <inertia ixx="0.0001666666666666667" ixy="0.0" ixz="0.0" iyy="0.0001666666666666667" iyz="0.0" izz="0.0001666666666666667"/>
    </inertial>
    <visual>
      <origin rpy="0.0 0.0 0.0" xyz="0.0 0.0 0.0"/>
      <geometry>
        <sphere radius="0.05"/>
      </geometry>
    </visual>
    <collision>
      <origin rpy="0.0 0.0 0.0" xyz="0.0 0.0 0.0"/>
      <geometry>
        <sphere radius="0.05"/>
      </geometry>
    </collision>
  </link>
  <joint name="wheel_joint_1" type="continuous">
    <parent link="ball_1"/>
    <child link="wheel_1"/>
    <origin rpy="0.0 0.0 0.0" xyz="0.0 0.0 0.05"/>
    <axis xyz="0 0 -1"/>
    <limit effort="132" velocity="15.5"/>
    <!-- 23 Nm, 1
            rad/s-->
  </joint>
  <link name="wheel_1">
    <inertial>
      <origin xyz="0.0 0.0 0.00015403767"/>
      <mass value="1.8569388"/>
      <inertia ixx="0.008637359099999999" ixy="0.0" ixz="-0.0" iyy="0.0086373644" iyz="-0.0" izz="0.016376551"/>
    </inertial>
    <visual>
      <origin rpy="0.0 0.0 0.0" xyz="0.0 0.0 0.0"/>
      <geometry>
        <mesh filename="/root/ibrido_ws/src/iit-kyon-ros-pkg/kyon_urdf/meshes/mesh_wheel23.stl" scale="0.001 0.001 -0.001"/>
      </geometry>
      <material name="black"/>
    </visual>
    <collision>
      <origin rpy="0 0 0" xyz="0 0 0"/>
      <geometry>
        <mesh filename="/root/ibrido_ws/src/iit-kyon-ros-pkg/kyon_urdf/meshes/collision/mesh_wheel23.stl" scale="0.001 0.001 -0.001"/>
      </geometry>
      <material name="black"/>
    </collision>
  </link>
  <!-- joints -->
  <joint name="hip_roll_1" type="revolute">
    <parent link="pelvis"/>
    <child link="hip_roll_motor_1"/>
    <origin rpy="0.0 1.57079632679 0.0" xyz="0.4 0.225 0.0"/>
    <axis xyz="0 0 1"/>
    <limit effort="132" lower="-2.03" upper="2.51" velocity="15.5"/>
    <!-- 200 Nm, 1 rad/s-->
  </joint>
  <joint name="hip_pitch_stator_1" type="fixed">
    <parent link="hip_roll_motor_1"/>
    <child link="hip_pitch_motor_1"/>
    <origin rpy="-1.57079632679 0.0 0.0" xyz="0.0 0.07 0.0"/>
  </joint>
  <joint name="knee_pitch_stator_1" type="fixed">
    <parent link="hip_pitch_motor_1"/>
    <child link="knee_pitch_motor_1"/>
    <origin rpy="0.0 0.0 0.0" xyz="0.0 0.0 0.0"/>
  </joint>
  <joint name="hip_pitch_1" type="revolute">
    <parent link="hip_pitch_motor_1"/>
    <child link="upper_leg_1"/>
    <origin rpy="0.0 0.0 0.0" xyz="0.0 -0.0 0.0"/>
    <axis xyz="0 0 1"/>
    <limit effort="132" lower="-2.4056" upper="2.4056" velocity="15.5"/>
    <!-- 200 Nm, 1 rad/s-->
  </joint>
  <joint name="knee_pitch_1" type="revolute">
    <parent link="upper_leg_1"/>
    <child link="lower_leg_1"/>
    <origin rpy="0.0 0.0 0.0" xyz="0.35 0.0 0.0"/>
    <axis xyz="0 0 1"/>
    <limit effort="132" lower="-2.4056" upper="2.4056" velocity="15.5"/>
    <!-- 200 Nm, 1 rad/s-->
  </joint>
  <joint name="ball_joint_1" type="fixed">
    <parent link="lower_leg_1"/>
    <child link="ball_1"/>
    <origin rpy="0.0 0.0 0.0" xyz="0.3 0.0 0.0"/>
  </joint>
  <!-- links -->
  <link name="hip_roll_motor_2">
    <inertial>
      <origin xyz="0.0 0.0 0.0"/>
      <mass value="1.8"/>
      <inertia ixx="0.001893666666666667" ixy="0.0" ixz="0.0" iyy="0.001893666666666667" iyz="0.0" izz="0.002254000000000001"/>
    </inertial>
    <visual>
      <origin rpy="0.0 0.0 0.0" xyz="0.0 0.0 0.0"/>
      <geometry>
        <cylinder length="0.1" radius="0.07"/>
      </geometry>
      <material name="dark_grey"/>
    </visual>
    <collision>
      <origin rpy="0.0 0.0 0.0" xyz="0.0 0.0 0.0"/>
      <geometry>
        <cylinder length="0.1" radius="0.07"/>
      </geometry>
    </collision>
  </link>
  <link name="hip_pitch_motor_2">
    <inertial>
      <origin xyz="0.0 0.0 0.0"/>
      <mass value="1.8"/>
      <inertia ixx="0.001893666666666667" ixy="0.0" ixz="0.0" iyy="0.001893666666666667" iyz="0.0" izz="0.002254000000000001"/>
    </inertial>
    <visual>
      <origin rpy="0.0 0.0 0.0" xyz="0.0 0.0 0.0"/>
      <geometry>
        <cylinder length="0.1" radius="0.07"/>
      </geometry>
      <material name="dark_grey"/>
    </visual>
    <collision>
      <origin rpy="0.0 0.0 0.0" xyz="0.0 0.0 0.0"/>
      <geometry>
        <cylinder length="0.1" radius="0.07"/>
      </geometry>
    </collision>
  </link>
  <link name="knee_pitch_motor_2">
    <inertial>
      <origin xyz="0.0 0.0 0.0"/>
      <mass value="1.8"/>
      <inertia ixx="0.001893666666666667" ixy="0.0" ixz="0.0" iyy="0.001893666666666667" iyz="0.0" izz="0.002254000000000001"/>
    </inertial>
    <visual>
      <origin rpy="0.0 0.0 0.0" xyz="0.0 0.0 0.0"/>
      <geometry>
        <cylinder length="0.1" radius="0.07"/>
      </geometry>
      <material name="dark_grey"/>
    </visual>
    <collision>
      <origin rpy="0.0 0.0 0.0" xyz="0.0 0.0 0.0"/>
      <geometry>
        <cylinder length="0.1" radius="0.07"/>
      </geometry>
    </collision>
  </link>
  <link name="upper_leg_2">
    <inertial>
      <origin xyz="0.175 0.0 0.0"/>
      <mass value="2.0"/>
      <inertia ixx="0.003333333333333334" ixy="0.0" ixz="0.0" iyy="0.02208333333333333" iyz="0.0" izz="0.02208333333333333"/>
    </inertial>
    <origin rpy="0.0 0.0 0.0" xyz="0.0 0.0 0.0"/>
    <visual>
      <origin rpy="0.0 0.0 0.0" xyz="0.175 0.0 0.0"/>
      <geometry>
        <box size="0.35 0.1 0.1"/>
      </geometry>
      <material name="dark_grey"/>
    </visual>
    <collision>
      <origin rpy="0.0 0.0 0.0" xyz="0.175 0.0 0.0"/>
      <geometry>
        <box size="0.35 0.1 0.1"/>
      </geometry>
    </collision>
  </link>
  <link name="lower_leg_2">
    <inertial>
      <origin xyz="0.15 0.0 0.0"/>
      <mass value="1.0"/>
      <inertia ixx="0.00041666666666666675" ixy="0.0" ixz="0.0" iyy="0.007708333333333333" iyz="0.0" izz="0.007708333333333333"/>
    </inertial>
    <visual>
      <origin rpy="0.0 0.0 0.0" xyz="0.15 0.0 0.0"/>
      <geometry>
        <box size="0.3 0.05 0.05"/>
      </geometry>
      <material name="dark_grey"/>
    </visual>
    <collision>
      <origin rpy="0.0 0.0 0.0" xyz="0.15 0.0 0.0"/>
      <geometry>
        <box size="0.3 0.05 0.05"/>
      </geometry>
    </collision>
  </link>
  <link name="ball_2">
    <inertial>
      <origin xyz="0.0 0.0 0.0"/>
      <mass value="0.1"/>
      <inertia ixx="0.0001666666666666667" ixy="0.0" ixz="0.0" iyy="0.0001666666666666667" iyz="0.0" izz="0.0001666666666666667"/>
    </inertial>
    <visual>
      <origin rpy="0.0 0.0 0.0" xyz="0.0 0.0 0.0"/>
      <geometry>
        <sphere radius="0.05"/>
      </geometry>
    </visual>
    <collision>
      <origin rpy="0.0 0.0 0.0" xyz="0.0 0.0 0.0"/>
      <geometry>
        <sphere radius="0.05"/>
      </geometry>
    </collision>
  </link>
  <joint name="wheel_joint_2" type="continuous">
    <parent link="ball_2"/>
    <child link="wheel_2"/>
    <origin rpy="0.0 0.0 0.0" xyz="0.0 0.0 -0.05"/>
    <axis xyz="0 0 1"/>
    <limit effort="132" velocity="15.5"/>
    <!-- 23 Nm, 1
            rad/s-->
  </joint>
  <link name="wheel_2">
    <inertial>
      <origin xyz="0.0 0.0 -0.00015403767"/>
      <mass value="1.8569388"/>
      <inertia ixx="0.008637359099999999" ixy="0.0" ixz="0.0" iyy="0.0086373644" iyz="0.0" izz="0.016376551"/>
    </inertial>
    <visual>
      <origin rpy="0.0 0.0 0.0" xyz="0.0 0.0 0.0"/>
      <geometry>
        <mesh filename="/root/ibrido_ws/src/iit-kyon-ros-pkg/kyon_urdf/meshes/mesh_wheel23.stl" scale="0.001 0.001 0.001"/>
      </geometry>
      <material name="black"/>
    </visual>
    <collision>
      <origin rpy="0 0 0" xyz="0 0 0"/>
      <geometry>
        <mesh filename="/root/ibrido_ws/src/iit-kyon-ros-pkg/kyon_urdf/meshes/collision/mesh_wheel23.stl" scale="0.001 0.001 0.001"/>
      </geometry>
      <material name="black"/>
    </collision>
  </link>
  <!-- joints -->
  <joint name="hip_roll_2" type="revolute">
    <parent link="pelvis"/>
    <child link="hip_roll_motor_2"/>
    <origin rpy="0.0 1.57079632679 0.0" xyz="0.4 -0.225 0.0"/>
    <axis xyz="0 0 1"/>
    <limit effort="132" lower="-2.51" upper="2.03" velocity="15.5"/>
    <!-- 200 Nm, 1 rad/s-->
  </joint>
  <joint name="hip_pitch_stator_2" type="fixed">
    <parent link="hip_roll_motor_2"/>
    <child link="hip_pitch_motor_2"/>
    <origin rpy="-1.57079632679 0.0 0.0" xyz="0.0 -0.07 0.0"/>
  </joint>
  <joint name="knee_pitch_stator_2" type="fixed">
    <parent link="hip_pitch_motor_2"/>
    <child link="knee_pitch_motor_2"/>
    <origin rpy="0.0 0.0 0.0" xyz="0.0 0.0 0.0"/>
  </joint>
  <joint name="hip_pitch_2" type="revolute">
    <parent link="hip_pitch_motor_2"/>
    <child link="upper_leg_2"/>
    <origin rpy="0.0 0.0 0.0" xyz="0.0 0.0 0.0"/>
    <axis xyz="0 0 1"/>
    <limit effort="132" lower="-2.3266" upper="2.3266" velocity="15.5"/>
    <!-- 200 Nm, 1 rad/s-->
  </joint>
  <joint name="knee_pitch_2" type="revolute">
    <parent link="upper_leg_2"/>
    <child link="lower_leg_2"/>
    <origin rpy="0.0 0.0 0.0" xyz="0.35 0.0 0.0"/>
    <axis xyz="0 0 1"/>
    <limit effort="132" lower="-2.3266" upper="2.3266" velocity="15.5"/>
    <!-- 200 Nm, 1 rad/s-->
  </joint>
  <joint name="ball_joint_2" type="fixed">
    <parent link="lower_leg_2"/>
    <child link="ball_2"/>
    <origin rpy="0.0 0.0 0.0" xyz="0.3 0.0 0.0"/>
  </joint>
  <!-- links -->
  <link name="hip_roll_motor_3">
    <inertial>
      <origin xyz="0.0 0.0 0.0"/>
      <mass value="1.8"/>
      <inertia ixx="0.001893666666666667" ixy="0.0" ixz="0.0" iyy="0.001893666666666667" iyz="0.0" izz="0.002254000000000001"/>
    </inertial>
    <visual>
      <origin rpy="0.0 0.0 0.0" xyz="0.0 0.0 0.0"/>
      <geometry>
        <cylinder length="0.1" radius="0.07"/>
      </geometry>
      <material name="dark_grey"/>
    </visual>
    <collision>
      <origin rpy="0.0 0.0 0.0" xyz="0.0 0.0 0.0"/>
      <geometry>
        <cylinder length="0.1" radius="0.07"/>
      </geometry>
    </collision>
  </link>
  <link name="hip_pitch_motor_3">
    <inertial>
      <origin xyz="0.0 0.0 0.0"/>
      <mass value="1.8"/>
      <inertia ixx="0.001893666666666667" ixy="0.0" ixz="0.0" iyy="0.001893666666666667" iyz="0.0" izz="0.002254000000000001"/>
    </inertial>
    <visual>
      <origin rpy="0.0 0.0 0.0" xyz="0.0 0.0 0.0"/>
      <geometry>
        <cylinder length="0.1" radius="0.07"/>
      </geometry>
      <material name="dark_grey"/>
    </visual>
    <collision>
      <origin rpy="0.0 0.0 0.0" xyz="0.0 0.0 0.0"/>
      <geometry>
        <cylinder length="0.1" radius="0.07"/>
      </geometry>
    </collision>
  </link>
  <link name="knee_pitch_motor_3">
    <inertial>
      <origin xyz="0.0 0.0 0.0"/>
      <mass value="1.8"/>
      <inertia ixx="0.001893666666666667" ixy="0.0" ixz="0.0" iyy="0.001893666666666667" iyz="0.0" izz="0.002254000000000001"/>
    </inertial>
    <visual>
      <origin rpy="0.0 0.0 0.0" xyz="0.0 0.0 0.0"/>
      <geometry>
        <cylinder length="0.1" radius="0.07"/>
      </geometry>
      <material name="dark_grey"/>
    </visual>
    <collision>
      <origin rpy="0.0 0.0 0.0" xyz="0.0 0.0 0.0"/>
      <geometry>
        <cylinder length="0.1" radius="0.07"/>
      </geometry>
    </collision>
  </link>
  <link name="upper_leg_3">
    <inertial>
      <origin xyz="0.175 0.0 0.0"/>
      <mass value="2.0"/>
      <inertia ixx="0.003333333333333334" ixy="0.0" ixz="0.0" iyy="0.02208333333333333" iyz="0.0" izz="0.02208333333333333"/>
    </inertial>
    <origin rpy="0.0 0.0 0.0" xyz="0.0 0.0 0.0"/>
    <visual>
      <origin rpy="0.0 0.0 0.0" xyz="0.175 0.0 0.0"/>
      <geometry>
        <box size="0.35 0.1 0.1"/>
      </geometry>
      <material name="dark_grey"/>
    </visual>
    <collision>
      <origin rpy="0.0 0.0 0.0" xyz="0.175 0.0 0.0"/>
      <geometry>
        <box size="0.35 0.1 0.1"/>
      </geometry>
    </collision>
  </link>
  <link name="lower_leg_3">
    <inertial>
      <origin xyz="0.15 0.0 0.0"/>
      <mass value="1.0"/>
      <inertia ixx="0.00041666666666666675" ixy="0.0" ixz="0.0" iyy="0.007708333333333333" iyz="0.0" izz="0.007708333333333333"/>
    </inertial>
    <visual>
      <origin rpy="0.0 0.0 0.0" xyz="0.15 0.0 0.0"/>
      <geometry>
        <box size="0.3 0.05 0.05"/>
      </geometry>
      <material name="dark_grey"/>
    </visual>
    <collision>
      <origin rpy="0.0 0.0 0.0" xyz="0.15 0.0 0.0"/>
      <geometry>
        <box size="0.3 0.05 0.05"/>
      </geometry>
    </collision>
  </link>
  <link name="ball_3">
    <inertial>
      <origin xyz="0.0 0.0 0.0"/>
      <mass value="0.1"/>
      <inertia ixx="0.0001666666666666667" ixy="0.0" ixz="0.0" iyy="0.0001666666666666667" iyz="0.0" izz="0.0001666666666666667"/>
    </inertial>
    <visual>
      <origin rpy="0.0 0.0 0.0" xyz="0.0 0.0 0.0"/>
      <geometry>
        <sphere radius="0.05"/>
      </geometry>
    </visual>
    <collision>
      <origin rpy="0.0 0.0 0.0" xyz="0.0 0.0 0.0"/>
      <geometry>
        <sphere radius="0.05"/>
      </geometry>
    </collision>
  </link>
  <joint name="wheel_joint_3" type="continuous">
    <parent link="ball_3"/>
    <child link="wheel_3"/>
    <origin rpy="0.0 0.0 0.0" xyz="0.0 0.0 0.05"/>
    <axis xyz="0 0 -1"/>
    <limit effort="132" velocity="15.5"/>
    <!-- 23 Nm, 1
            rad/s-->
  </joint>
  <link name="wheel_3">
    <inertial>
      <origin xyz="0.0 0.0 0.00015403767"/>
      <mass value="1.8569388"/>
      <inertia ixx="0.008637359099999999" ixy="0.0" ixz="-0.0" iyy="0.0086373644" iyz="-0.0" izz="0.016376551"/>
    </inertial>
    <visual>
      <origin rpy="0.0 0.0 0.0" xyz="0.0 0.0 0.0"/>
      <geometry>
        <mesh filename="/root/ibrido_ws/src/iit-kyon-ros-pkg/kyon_urdf/meshes/mesh_wheel23.stl" scale="0.001 0.001 -0.001"/>
      </geometry>
      <material name="black"/>
    </visual>
    <collision>
      <origin rpy="0 0 0" xyz="0 0 0"/>
      <geometry>
        <mesh filename="/root/ibrido_ws/src/iit-kyon-ros-pkg/kyon_urdf/meshes/collision/mesh_wheel23.stl" scale="0.001 0.001 -0.001"/>
      </geometry>
      <material name="black"/>
    </collision>
  </link>
  <!-- joints -->
  <joint name="hip_roll_3" type="revolute">
    <parent link="pelvis"/>
    <child link="hip_roll_motor_3"/>
    <origin rpy="0.0 1.57079632679 0.0" xyz="-0.4 0.225 0.0"/>
    <axis xyz="0 0 1"/>
    <limit effort="132" lower="-2.51" upper="2.03" velocity="15.5"/>
    <!-- 200 Nm, 1 rad/s-->
  </joint>
  <joint name="hip_pitch_stator_3" type="fixed">
    <parent link="hip_roll_motor_3"/>
    <child link="hip_pitch_motor_3"/>
    <origin rpy="-1.57079632679 0.0 0.0" xyz="0.0 0.07 0.0"/>
  </joint>
  <joint name="knee_pitch_stator_3" type="fixed">
    <parent link="hip_pitch_motor_3"/>
    <child link="knee_pitch_motor_3"/>
    <origin rpy="0.0 0.0 0.0" xyz="0.0 0.0 0.0"/>
  </joint>
  <joint name="hip_pitch_3" type="revolute">
    <parent link="hip_pitch_motor_3"/>
    <child link="upper_leg_3"/>
    <origin rpy="0.0 0.0 0.0" xyz="0.0 -0.0 0.0"/>
    <axis xyz="0 0 1"/>
    <limit effort="132" lower="-2.4696" upper="2.4696" velocity="15.5"/>
    <!-- 200 Nm, 1 rad/s-->
  </joint>
  <joint name="knee_pitch_3" type="revolute">
    <parent link="upper_leg_3"/>
    <child link="lower_leg_3"/>
    <origin rpy="0.0 0.0 0.0" xyz="0.35 0.0 0.0"/>
    <axis xyz="0 0 1"/>
    <limit effort="132" lower="-2.4696" upper="2.4696" velocity="15.5"/>
    <!-- 200 Nm, 1 rad/s-->
  </joint>
  <joint name="ball_joint_3" type="fixed">
    <parent link="lower_leg_3"/>
    <child link="ball_3"/>
    <origin rpy="0.0 0.0 0.0" xyz="0.3 0.0 0.0"/>
  </joint>
  <!-- links -->
  <link name="hip_roll_motor_4">
    <inertial>
      <origin xyz="0.0 0.0 0.0"/>
      <mass value="1.8"/>
      <inertia ixx="0.001893666666666667" ixy="0.0" ixz="0.0" iyy="0.001893666666666667" iyz="0.0" izz="0.002254000000000001"/>
    </inertial>
    <visual>
      <origin rpy="0.0 0.0 0.0" xyz="0.0 0.0 0.0"/>
      <geometry>
        <cylinder length="0.1" radius="0.07"/>
      </geometry>
      <material name="dark_grey"/>
    </visual>
    <collision>
      <origin rpy="0.0 0.0 0.0" xyz="0.0 0.0 0.0"/>
      <geometry>
        <cylinder length="0.1" radius="0.07"/>
      </geometry>
    </collision>
  </link>
  <link name="hip_pitch_motor_4">
    <inertial>
      <origin xyz="0.0 0.0 0.0"/>
      <mass value="1.8"/>
      <inertia ixx="0.001893666666666667" ixy="0.0" ixz="0.0" iyy="0.001893666666666667" iyz="0.0" izz="0.002254000000000001"/>
    </inertial>
    <visual>
      <origin rpy="0.0 0.0 0.0" xyz="0.0 0.0 0.0"/>
      <geometry>
        <cylinder length="0.1" radius="0.07"/>
      </geometry>
      <material name="dark_grey"/>
    </visual>
    <collision>
      <origin rpy="0.0 0.0 0.0" xyz="0.0 0.0 0.0"/>
      <geometry>
        <cylinder length="0.1" radius="0.07"/>
      </geometry>
    </collision>
  </link>
  <link name="knee_pitch_motor_4">
    <inertial>
      <origin xyz="0.0 0.0 0.0"/>
      <mass value="1.8"/>
      <inertia ixx="0.001893666666666667" ixy="0.0" ixz="0.0" iyy="0.001893666666666667" iyz="0.0" izz="0.002254000000000001"/>
    </inertial>
    <visual>
      <origin rpy="0.0 0.0 0.0" xyz="0.0 0.0 0.0"/>
      <geometry>
        <cylinder length="0.1" radius="0.07"/>
      </geometry>
      <material name="dark_grey"/>
    </visual>
    <collision>
      <origin rpy="0.0 0.0 0.0" xyz="0.0 0.0 0.0"/>
      <geometry>
        <cylinder length="0.1" radius="0.07"/>
      </geometry>
    </collision>
  </link>
  <link name="upper_leg_4">
    <inertial>
      <origin xyz="0.175 0.0 0.0"/>
      <mass value="2.0"/>
      <inertia ixx="0.003333333333333334" ixy="0.0" ixz="0.0" iyy="0.02208333333333333" iyz="0.0" izz="0.02208333333333333"/>
    </inertial>
    <origin rpy="0.0 0.0 0.0" xyz="0.0 0.0 0.0"/>
    <visual>
      <origin rpy="0.0 0.0 0.0" xyz="0.175 0.0 0.0"/>
      <geometry>
        <box size="0.35 0.1 0.1"/>
      </geometry>
      <material name="dark_grey"/>
    </visual>
    <collision>
      <origin rpy="0.0 0.0 0.0" xyz="0.175 0.0 0.0"/>
      <geometry>
        <box size="0.35 0.1 0.1"/>
      </geometry>
    </collision>
  </link>
  <link name="lower_leg_4">
    <inertial>
      <origin xyz="0.15 0.0 0.0"/>
      <mass value="1.0"/>
      <inertia ixx="0.00041666666666666675" ixy="0.0" ixz="0.0" iyy="0.007708333333333333" iyz="0.0" izz="0.007708333333333333"/>
    </inertial>
    <visual>
      <origin rpy="0.0 0.0 0.0" xyz="0.15 0.0 0.0"/>
      <geometry>
        <box size="0.3 0.05 0.05"/>
      </geometry>
      <material name="dark_grey"/>
    </visual>
    <collision>
      <origin rpy="0.0 0.0 0.0" xyz="0.15 0.0 0.0"/>
      <geometry>
        <box size="0.3 0.05 0.05"/>
      </geometry>
    </collision>
  </link>
  <link name="ball_4">
    <inertial>
      <origin xyz="0.0 0.0 0.0"/>
      <mass value="0.1"/>
      <inertia ixx="0.0001666666666666667" ixy="0.0" ixz="0.0" iyy="0.0001666666666666667" iyz="0.0" izz="0.0001666666666666667"/>
    </inertial>
    <visual>
      <origin rpy="0.0 0.0 0.0" xyz="0.0 0.0 0.0"/>
      <geometry>
        <sphere radius="0.05"/>
      </geometry>
    </visual>
    <collision>
      <origin rpy="0.0 0.0 0.0" xyz="0.0 0.0 0.0"/>
      <geometry>
        <sphere radius="0.05"/>
      </geometry>
    </collision>
  </link>
  <joint name="wheel_joint_4" type="continuous">
    <parent link="ball_4"/>
    <child link="wheel_4"/>
    <origin rpy="0.0 0.0 0.0" xyz="0.0 0.0 -0.05"/>
    <axis xyz="0 0 1"/>
    <limit effort="132" velocity="15.5"/>
    <!-- 23 Nm, 1
            rad/s-->
  </joint>
  <link name="wheel_4">
    <inertial>
      <origin xyz="0.0 0.0 -0.00015403767"/>
      <mass value="1.8569388"/>
      <inertia ixx="0.008637359099999999" ixy="0.0" ixz="0.0" iyy="0.0086373644" iyz="0.0" izz="0.016376551"/>
    </inertial>
    <visual>
      <origin rpy="0.0 0.0 0.0" xyz="0.0 0.0 0.0"/>
      <geometry>
        <mesh filename="/root/ibrido_ws/src/iit-kyon-ros-pkg/kyon_urdf/meshes/mesh_wheel23.stl" scale="0.001 0.001 0.001"/>
      </geometry>
      <material name="black"/>
    </visual>
    <collision>
      <origin rpy="0 0 0" xyz="0 0 0"/>
      <geometry>
        <mesh filename="/root/ibrido_ws/src/iit-kyon-ros-pkg/kyon_urdf/meshes/collision/mesh_wheel23.stl" scale="0.001 0.001 0.001"/>
      </geometry>
      <material name="black"/>
    </collision>
  </link>
  <!-- joints -->
  <joint name="hip_roll_4" type="revolute">
    <parent link="pelvis"/>
    <child link="hip_roll_motor_4"/>
    <origin rpy="0.0 1.57079632679 0.0" xyz="-0.4 -0.225 0.0"/>
    <axis xyz="0 0 1"/>
    <limit effort="132" lower="-2.03" upper="2.51" velocity="15.5"/>
    <!-- 200 Nm, 1 rad/s-->
  </joint>
  <joint name="hip_pitch_stator_4" type="fixed">
    <parent link="hip_roll_motor_4"/>
    <child link="hip_pitch_motor_4"/>
    <origin rpy="-1.57079632679 0.0 0.0" xyz="0.0 -0.07 0.0"/>
  </joint>
  <joint name="knee_pitch_stator_4" type="fixed">
    <parent link="hip_pitch_motor_4"/>
    <child link="knee_pitch_motor_4"/>
    <origin rpy="0.0 0.0 0.0" xyz="0.0 0.0 0.0"/>
  </joint>
  <joint name="hip_pitch_4" type="revolute">
    <parent link="hip_pitch_motor_4"/>
    <child link="upper_leg_4"/>
    <origin rpy="0.0 0.0 0.0" xyz="0.0 0.0 0.0"/>
    <axis xyz="0 0 1"/>
    <limit effort="132" lower="-2.3426" upper="2.3426" velocity="15.5"/>
    <!-- 200 Nm, 1 rad/s-->
  </joint>
  <joint name="knee_pitch_4" type="revolute">
    <parent link="upper_leg_4"/>
    <child link="lower_leg_4"/>
    <origin rpy="0.0 0.0 0.0" xyz="0.35 0.0 0.0"/>
    <axis xyz="0 0 1"/>
    <limit effort="132" lower="-2.3426" upper="2.3426" velocity="15.5"/>
    <!-- 200 Nm, 1 rad/s-->
  </joint>
  <joint name="ball_joint_4" type="fixed">
    <parent link="lower_leg_4"/>
    <child link="ball_4"/>
    <origin rpy="0.0 0.0 0.0" xyz="0.3 0.0 0.0"/>
  </joint>
  <!-- ************ Control frames ************ -->
  <!--xacro:include filename="$(find pholus_urdf)/urdf/control_frames.urdf.xacro"/-->
  <link name="world"/>
  <joint name="reference" type="floating">
    <parent link="world"/>
    <child link="base_link"/>
  </joint>
</robot>
